[2022-11-21 21:52:02,621] {taskinstance.py:1035} INFO - Dependencies all met for <TaskInstance: bash_operator.view_dir manual__2022-11-21T21:45:02.928692+00:00 [queued]>
[2022-11-21 21:52:02,644] {taskinstance.py:1035} INFO - Dependencies all met for <TaskInstance: bash_operator.view_dir manual__2022-11-21T21:45:02.928692+00:00 [queued]>
[2022-11-21 21:52:02,645] {taskinstance.py:1241} INFO - 
--------------------------------------------------------------------------------
[2022-11-21 21:52:02,646] {taskinstance.py:1242} INFO - Starting attempt 2 of 2
[2022-11-21 21:52:02,647] {taskinstance.py:1243} INFO - 
--------------------------------------------------------------------------------
[2022-11-21 21:52:02,660] {taskinstance.py:1262} INFO - Executing <Task(BashOperator): view_dir> on 2022-11-21 21:45:02.928692+00:00
[2022-11-21 21:52:02,671] {standard_task_runner.py:76} INFO - Running: ['***', 'tasks', 'run', 'bash_operator', 'view_dir', 'manual__2022-11-21T21:45:02.928692+00:00', '--job-id', '12', '--raw', '--subdir', 'DAGS_FOLDER/bash_example.py', '--cfg-path', '/tmp/tmp7f8zwg6r', '--error-file', '/tmp/tmpc7mbxsj_']
[2022-11-21 21:52:02,672] {standard_task_runner.py:77} INFO - Job 12: Subtask view_dir
[2022-11-21 21:52:02,667] {standard_task_runner.py:52} INFO - Started process 759 to run task
[2022-11-21 21:52:02,731] {logging_mixin.py:109} INFO - Running <TaskInstance: bash_operator.view_dir manual__2022-11-21T21:45:02.928692+00:00 [running]> on host e6f0f1db9976
[2022-11-21 21:52:02,786] {taskinstance.py:1414} INFO - Exporting the following env vars:
AIRFLOW_CTX_DAG_OWNER=***
AIRFLOW_CTX_DAG_ID=bash_operator
AIRFLOW_CTX_TASK_ID=view_dir
AIRFLOW_CTX_EXECUTION_DATE=2022-11-21T21:45:02.928692+00:00
AIRFLOW_CTX_DAG_RUN_ID=manual__2022-11-21T21:45:02.928692+00:00
[2022-11-21 21:52:02,788] {subprocess.py:62} INFO - Tmp dir root location: 
 /tmp
[2022-11-21 21:52:02,789] {subprocess.py:74} INFO - Running command: ['bash', '-c', 'ls $(pwd)/***/']
[2022-11-21 21:52:02,800] {subprocess.py:85} INFO - Output:
[2022-11-21 21:52:02,805] {subprocess.py:89} INFO - ls: cannot access '/tmp/***tmpnrjf3jm5/***/': No such file or directory
[2022-11-21 21:52:02,806] {subprocess.py:93} INFO - Command exited with return code 2
[2022-11-21 21:52:02,810] {taskinstance.py:1686} ERROR - Task failed with exception
Traceback (most recent call last):
  File "/home/airflow/.local/lib/python3.6/site-packages/airflow/models/taskinstance.py", line 1324, in _run_raw_task
    self._execute_task_with_callbacks(context)
  File "/home/airflow/.local/lib/python3.6/site-packages/airflow/models/taskinstance.py", line 1443, in _execute_task_with_callbacks
    result = self._execute_task(context, self.task)
  File "/home/airflow/.local/lib/python3.6/site-packages/airflow/models/taskinstance.py", line 1499, in _execute_task
    result = execute_callable(context=context)
  File "/home/airflow/.local/lib/python3.6/site-packages/airflow/operators/bash.py", line 188, in execute
    f'Bash command failed. The command returned a non-zero exit code {result.exit_code}.'
airflow.exceptions.AirflowException: Bash command failed. The command returned a non-zero exit code 2.
[2022-11-21 21:52:02,827] {taskinstance.py:1280} INFO - Marking task as FAILED. dag_id=bash_operator, task_id=view_dir, execution_date=20221121T214502, start_date=20221121T215202, end_date=20221121T215202
[2022-11-21 21:52:02,842] {standard_task_runner.py:91} ERROR - Failed to execute job 12 for task view_dir
Traceback (most recent call last):
  File "/home/airflow/.local/lib/python3.6/site-packages/airflow/task/task_runner/standard_task_runner.py", line 85, in _start_by_fork
    args.func(args, dag=self.dag)
  File "/home/airflow/.local/lib/python3.6/site-packages/airflow/cli/cli_parser.py", line 48, in command
    return func(*args, **kwargs)
  File "/home/airflow/.local/lib/python3.6/site-packages/airflow/utils/cli.py", line 92, in wrapper
    return f(*args, **kwargs)
  File "/home/airflow/.local/lib/python3.6/site-packages/airflow/cli/commands/task_command.py", line 292, in task_run
    _run_task_by_selected_method(args, dag, ti)
  File "/home/airflow/.local/lib/python3.6/site-packages/airflow/cli/commands/task_command.py", line 107, in _run_task_by_selected_method
    _run_raw_task(args, ti)
  File "/home/airflow/.local/lib/python3.6/site-packages/airflow/cli/commands/task_command.py", line 184, in _run_raw_task
    error_file=args.error_file,
  File "/home/airflow/.local/lib/python3.6/site-packages/airflow/utils/session.py", line 70, in wrapper
    return func(*args, session=session, **kwargs)
  File "/home/airflow/.local/lib/python3.6/site-packages/airflow/models/taskinstance.py", line 1324, in _run_raw_task
    self._execute_task_with_callbacks(context)
  File "/home/airflow/.local/lib/python3.6/site-packages/airflow/models/taskinstance.py", line 1443, in _execute_task_with_callbacks
    result = self._execute_task(context, self.task)
  File "/home/airflow/.local/lib/python3.6/site-packages/airflow/models/taskinstance.py", line 1499, in _execute_task
    result = execute_callable(context=context)
  File "/home/airflow/.local/lib/python3.6/site-packages/airflow/operators/bash.py", line 188, in execute
    f'Bash command failed. The command returned a non-zero exit code {result.exit_code}.'
airflow.exceptions.AirflowException: Bash command failed. The command returned a non-zero exit code 2.
[2022-11-21 21:52:02,890] {local_task_job.py:154} INFO - Task exited with return code 1
[2022-11-21 21:52:02,936] {local_task_job.py:264} INFO - 0 downstream tasks scheduled from follow-on schedule check
