[2022-11-21 22:15:28,361] {taskinstance.py:1029} INFO - Dependencies not met for <TaskInstance: etl_example.transform_data scheduled__2022-11-21T21:00:00+00:00 [queued]>, dependency 'Trigger Rule' FAILED: Task's trigger rule 'all_success' requires all upstream tasks to have succeeded, but found 1 non-success(es). upstream_tasks_state={'total': 1, 'successes': 0, 'skipped': 0, 'failed': 0, 'upstream_failed': 0, 'done': 0}, upstream_task_ids={'extract_load_data'}
[2022-11-21 22:15:28,367] {local_task_job.py:99} INFO - Task is not able to be run
[2022-11-21 22:16:42,332] {taskinstance.py:1035} INFO - Dependencies all met for <TaskInstance: etl_example.transform_data scheduled__2022-11-21T21:00:00+00:00 [queued]>
[2022-11-21 22:16:42,385] {taskinstance.py:1035} INFO - Dependencies all met for <TaskInstance: etl_example.transform_data scheduled__2022-11-21T21:00:00+00:00 [queued]>
[2022-11-21 22:16:42,386] {taskinstance.py:1241} INFO - 
--------------------------------------------------------------------------------
[2022-11-21 22:16:42,387] {taskinstance.py:1242} INFO - Starting attempt 1 of 1
[2022-11-21 22:16:42,388] {taskinstance.py:1243} INFO - 
--------------------------------------------------------------------------------
[2022-11-21 22:16:42,404] {taskinstance.py:1262} INFO - Executing <Task(PythonOperator): transform_data> on 2022-11-21 21:00:00+00:00
[2022-11-21 22:16:42,413] {standard_task_runner.py:52} INFO - Started process 1843 to run task
[2022-11-21 22:16:42,417] {standard_task_runner.py:76} INFO - Running: ['***', 'tasks', 'run', 'etl_example', 'transform_data', 'scheduled__2022-11-21T21:00:00+00:00', '--job-id', '40', '--raw', '--subdir', 'DAGS_FOLDER/etl_example.py', '--cfg-path', '/tmp/tmpwbsrcerg', '--error-file', '/tmp/tmpbrg362gn']
[2022-11-21 22:16:42,418] {standard_task_runner.py:77} INFO - Job 40: Subtask transform_data
[2022-11-21 22:16:42,468] {logging_mixin.py:109} INFO - Running <TaskInstance: etl_example.transform_data scheduled__2022-11-21T21:00:00+00:00 [running]> on host e6f0f1db9976
[2022-11-21 22:16:42,520] {taskinstance.py:1414} INFO - Exporting the following env vars:
AIRFLOW_CTX_DAG_OWNER=***
AIRFLOW_CTX_DAG_ID=etl_example
AIRFLOW_CTX_TASK_ID=transform_data
AIRFLOW_CTX_EXECUTION_DATE=2022-11-21T21:00:00+00:00
AIRFLOW_CTX_DAG_RUN_ID=scheduled__2022-11-21T21:00:00+00:00
[2022-11-21 22:16:42,643] {taskinstance.py:1686} ERROR - Task failed with exception
Traceback (most recent call last):
  File "/home/airflow/.local/lib/python3.6/site-packages/airflow/models/taskinstance.py", line 1324, in _run_raw_task
    self._execute_task_with_callbacks(context)
  File "/home/airflow/.local/lib/python3.6/site-packages/airflow/models/taskinstance.py", line 1443, in _execute_task_with_callbacks
    result = self._execute_task(context, self.task)
  File "/home/airflow/.local/lib/python3.6/site-packages/airflow/models/taskinstance.py", line 1499, in _execute_task
    result = execute_callable(context=context)
  File "/home/airflow/.local/lib/python3.6/site-packages/airflow/operators/python.py", line 151, in execute
    return_value = self.execute_callable()
  File "/home/airflow/.local/lib/python3.6/site-packages/airflow/operators/python.py", line 162, in execute_callable
    return self.python_callable(*self.op_args, **self.op_kwargs)
  File "/opt/airflow/dags/etl_example.py", line 12, in _transform_data
    df.to_csv('/opt/airflow/datalake/silver/launches.csv', index=False)
  File "/home/airflow/.local/lib/python3.6/site-packages/pandas/core/generic.py", line 3170, in to_csv
    formatter.save()
  File "/home/airflow/.local/lib/python3.6/site-packages/pandas/io/formats/csvs.py", line 190, in save
    compression=dict(self.compression_args, method=self.compression),
  File "/home/airflow/.local/lib/python3.6/site-packages/pandas/io/common.py", line 493, in get_handle
    f = open(path_or_buf, mode, encoding=encoding, errors=errors, newline="")
FileNotFoundError: [Errno 2] No such file or directory: '/opt/airflow/datalake/silver/launches.csv'
[2022-11-21 22:16:42,661] {taskinstance.py:1280} INFO - Marking task as FAILED. dag_id=etl_example, task_id=transform_data, execution_date=20221121T210000, start_date=20221121T221642, end_date=20221121T221642
[2022-11-21 22:16:42,675] {standard_task_runner.py:91} ERROR - Failed to execute job 40 for task transform_data
Traceback (most recent call last):
  File "/home/airflow/.local/lib/python3.6/site-packages/airflow/task/task_runner/standard_task_runner.py", line 85, in _start_by_fork
    args.func(args, dag=self.dag)
  File "/home/airflow/.local/lib/python3.6/site-packages/airflow/cli/cli_parser.py", line 48, in command
    return func(*args, **kwargs)
  File "/home/airflow/.local/lib/python3.6/site-packages/airflow/utils/cli.py", line 92, in wrapper
    return f(*args, **kwargs)
  File "/home/airflow/.local/lib/python3.6/site-packages/airflow/cli/commands/task_command.py", line 292, in task_run
    _run_task_by_selected_method(args, dag, ti)
  File "/home/airflow/.local/lib/python3.6/site-packages/airflow/cli/commands/task_command.py", line 107, in _run_task_by_selected_method
    _run_raw_task(args, ti)
  File "/home/airflow/.local/lib/python3.6/site-packages/airflow/cli/commands/task_command.py", line 184, in _run_raw_task
    error_file=args.error_file,
  File "/home/airflow/.local/lib/python3.6/site-packages/airflow/utils/session.py", line 70, in wrapper
    return func(*args, session=session, **kwargs)
  File "/home/airflow/.local/lib/python3.6/site-packages/airflow/models/taskinstance.py", line 1324, in _run_raw_task
    self._execute_task_with_callbacks(context)
  File "/home/airflow/.local/lib/python3.6/site-packages/airflow/models/taskinstance.py", line 1443, in _execute_task_with_callbacks
    result = self._execute_task(context, self.task)
  File "/home/airflow/.local/lib/python3.6/site-packages/airflow/models/taskinstance.py", line 1499, in _execute_task
    result = execute_callable(context=context)
  File "/home/airflow/.local/lib/python3.6/site-packages/airflow/operators/python.py", line 151, in execute
    return_value = self.execute_callable()
  File "/home/airflow/.local/lib/python3.6/site-packages/airflow/operators/python.py", line 162, in execute_callable
    return self.python_callable(*self.op_args, **self.op_kwargs)
  File "/opt/airflow/dags/etl_example.py", line 12, in _transform_data
    df.to_csv('/opt/airflow/datalake/silver/launches.csv', index=False)
  File "/home/airflow/.local/lib/python3.6/site-packages/pandas/core/generic.py", line 3170, in to_csv
    formatter.save()
  File "/home/airflow/.local/lib/python3.6/site-packages/pandas/io/formats/csvs.py", line 190, in save
    compression=dict(self.compression_args, method=self.compression),
  File "/home/airflow/.local/lib/python3.6/site-packages/pandas/io/common.py", line 493, in get_handle
    f = open(path_or_buf, mode, encoding=encoding, errors=errors, newline="")
FileNotFoundError: [Errno 2] No such file or directory: '/opt/airflow/datalake/silver/launches.csv'
[2022-11-21 22:16:42,718] {local_task_job.py:154} INFO - Task exited with return code 1
[2022-11-21 22:16:42,763] {local_task_job.py:264} INFO - 0 downstream tasks scheduled from follow-on schedule check
